import { Component, ErrorInfo, ReactNode } from 'react';
import { AlertTriangle, RefreshCw } from 'lucide-react';

interface Props {
  children: ReactNode;
  fallback?: ReactNode;
}

interface State {
  hasError: boolean;
  error?: Error;
}

class ErrorBoundary extends Component<Props, State> {
  constructor(props: Props) {
    super(props);
    this.state = { hasError: false };
  }

  static getDerivedStateFromError(error: Error): State {
    return { hasError: true, error };
  }

  componentDidCatch(error: Error, errorInfo: ErrorInfo) {
    console.error('Error caught by boundary:', error, errorInfo);
  }

  handleRetry = () => {
    this.setState({ hasError: false, error: undefined });
  };

  render() {
    if (this.state.hasError) {
      if (this.props.fallback) {
        return this.props.fallback;
      }

      return (
        <div className="min-h-screen bg-gray-50 dark:bg-gray-900 flex items-center justify-center p-4">
          <div className="max-w-md w-full bg-white dark:bg-gray-800 rounded-lg shadow-lg p-6 text-center">
            <div className="flex justify-center mb-4">
              <AlertTriangle className="w-12 h-12 text-red-500" />
            </div>
            <h2 className="text-xl font-semibold text-gray-900 dark:text-white mb-2">
              Oops! Something went wrong
            </h2>
            <p className="text-gray-600 dark:text-gray-300 mb-6">
              We encountered an unexpected error. Please try refreshing the page.
            </p>
            <button
              onClick={this.handleRetry}
              className="flex items-center justify-center space-x-2 bg-blue-600 text-white px-4 py-2 rounded-lg hover:bg-blue-700 transition-colors mx-auto"
            >
              <RefreshCw className="w-4 h-4" />
              <span>Try Again</span>
            </button>
          </div>
        </div>
      );
    }

    return this.props.children;
  }
}

export default ErrorBoundary; 